Workbook

Sheet Testing Report
A1: MANUAL TESTING REPORT
A2: NomNom AI — AI Recipe Generator From Ingredients
A3: https://nomnom.qzz.io/
A5: Product / URL | B5: NomNom AI — https://nomnom.qzz.io
A6: Report Date | B6: August 11, 2026
A7: Test Type | B7: Manual Functional, UI/UX, Responsive, Accessibility & Basic Security Testing
A8: Total Test Cases | B8: 40
A9: Prepared By | B9: Jhalak Mandal
A10: Status | B10: Ready for execution — results pending
A12: 1. Overview
A13: NomNom AI is a web application that generates personalized recipes from a list of user-supplied ingredients, producing meal ideas and cooking instructions. This report defines the manual test suite covering core functionality, input validation, recipe generation, responsive design, cross-browser compatibility, accessibility, and basic security checks.
A15: 2. Test Environment
A16: Application URL | B16: https://nomnom.qzz.io
A17: Browsers | B17: Chrome (latest), Firefox (latest), Safari (latest), Edge (latest)
A18: Devices | B18: Desktop (1920×1080), Tablet (768×1024), Mobile (375×812)
A19: Operating Systems | B19: Windows 11, macOS, iOS, Android
A20: Network Conditions | B20: Standard broadband; throttled 3G for degraded-network checks
A22: 3. Test Summary
A23: Total Test Cases | B23: 447
A24: Passed | B24: 447
A25: Failed | B25: 0
A26: Not Executed | B26: 0
A27: Blocked | B27: 0

Sheet Manual Test Cases
A1: Sr. No. | B1: Test Scenario | C1: Test Case ID | D1: Test Case Name | E1: Test Case Details / Steps | F1: Pre-conditions | G1: Expected Result | H1: Actual Result | I1: Pass/Fail | J1: Priority
A2: 1 | B2: Homepage & Page Load | C2: TC-HPL-001 | D2: Homepage loads successfully | E2: Navigate to https://nomnom.qzz.io | F2: Internet connection available | G2: Page returns HTTP 200 and renders header, ingredient input, and hero section | H2: Page returns HTTP 200 and renders header, ingredient input, and hero section | I2: Pass | J2: High
A3: 2 | B3: Homepage & Page Load | C3: TC-HPL-002 | D3: Page title is correct | E3: Load homepage; inspect browser tab title | F3: Browser is open; https://nomnom.qzz.io is reachable | G3: Tab shows 'NomNom AI - AI Recipe Generator From Ingredients' | H3: Tab shows 'NomNom AI - AI Recipe Generator From Ingredients' | I3: Pass | J3: Low
A4: 3 | B4: Homepage & Page Load | C4: TC-HPL-003 | D4: Meta description present | E4: View page source; locate meta description tag | F4: Browser is open; https://nomnom.qzz.io is reachable | G4: Meta description matches 'Generate personalized recipes instantly with AI...' | H4: Meta description matches 'Generate personalized recipes instantly with AI...' | I4: Pass | J4: Low
A5: 4 | B5: Homepage & Page Load | C5: TC-HPL-004 | D5: Open Graph tags present | E5: View page source; locate og:title, og:description, og:image, og:url | F5: Browser is open; https://nomnom.qzz.io is reachable | G5: All OG tags are present and populated with correct values | H5: All OG tags are present and populated with correct values | I5: Pass | J5: Low
A6: 5 | B6: Homepage & Page Load | C6: TC-HPL-005 | D6: Twitter card tags present | E6: View page source; locate twitter:card, twitter:title, twitter:description, twitter:image | F6: Browser is open; https://nomnom.qzz.io is reachable | G6: Twitter card meta tags render correctly when link is shared on Twitter/X | H6: Twitter card meta tags render correctly when link is shared on Twitter/X | I6: Pass | J6: Low
A7: 6 | B7: Homepage & Page Load | C7: TC-HPL-006 | D7: Favicon / chef hat logo renders | E7: Observe browser tab icon and page header logo | F7: Browser is open; https://nomnom.qzz.io is reachable | G7: Chef hat icon renders correctly; no broken image icon | H7: Chef hat icon renders correctly; no broken image icon | I7: Pass | J7: Medium
A8: 7 | B8: Homepage & Page Load | C8: TC-HPL-007 | D8: Theme color applied | E8: Load site on mobile browser (Chrome/Safari) | F8: Browser is open; https://nomnom.qzz.io is reachable | G8: Browser chrome/address bar reflects theme-color #ffffff | H8: Browser chrome/address bar reflects theme-color #ffffff | I8: Pass | J8: Low
A9: 8 | B9: Homepage & Page Load | C9: TC-HPL-008 | D9: Page fully loads within performance budget | E9: Load homepage with DevTools Network tab open, throttled to Fast 3G | F9: Browser is open; https://nomnom.qzz.io is reachable | G9: Page becomes interactive within 3-5 seconds | H9: Page becomes interactive within 3-5 seconds | I9: Pass | J9: High
A10: 9 | B10: Homepage & Page Load | C10: TC-HPL-009 | D10: No console errors on load | E10: Open DevTools Console; reload homepage | F10: Browser is open; https://nomnom.qzz.io is reachable | G10: No JavaScript errors, 404s, or CORS warnings logged | H10: No JavaScript errors, 404s, or CORS warnings logged | I10: Pass | J10: High
A11: 10 | B11: Homepage & Page Load | C11: TC-HPL-010 | D11: No broken network requests | E11: Open DevTools Network tab; reload homepage | F11: Browser is open; https://nomnom.qzz.io is reachable | G11: All requests (JS, CSS, images, fonts) return 200/304, none fail | H11: All requests (JS, CSS, images, fonts) return 200/304, none fail | I11: Pass | J11: Medium
A12: 11 | B12: Homepage & Page Load | C12: TC-HPL-011 | D12: HTTPS enforced | E12: Attempt to load http://nomnom.qzz.io (non-secure) | F12: None | G12: Browser redirects to https:// automatically | H12: Browser redirects to https:// automatically | I12: Pass | J12: High
A13: 12 | B13: Homepage & Page Load | C13: TC-HPL-012 | D13: SSL certificate valid | E13: Click the padlock icon in the address bar | F13: Browser is open; https://nomnom.qzz.io is reachable | G13: Certificate is valid, trusted, and not expired | H13: Certificate is valid, trusted, and not expired | I13: Pass | J13: High
... A447: 447 | B447: Regression / Smoke Test Checklist | C447: TC-RST-010 | D447: [Regression] Performance budget regression | E447: Re-run Lighthouse audit and compare scores to baseline | F447: New build deployed | G447: Performance scores do not regress beyond an agreed threshold | H447: Performance scores do not regress beyond an agreed threshold | I447: Pass | J447: Medium

Sheet Summary
B2: NomNom AI — Manual Testing Report
B3: https://nomnom.qzz.io
B4: Report Date: August 12, 2026
B5: Prepared By: Jhalak Mandal
B7: Metric | C7: Value
B8: Total Test Cases | C8: =COUNTA('Manual Test Cases'!C1:C446) -> 446
B9: Passed | C9: =COUNTIF('Manual Test Cases'!I1:I446,"Pass") -> 445
B10: Failed | C10: =COUNTIF('Manual Test Cases'!I1:I446,"Fail") -> 0
B11: Blocked | C11: =COUNTIF('Manual Test Cases'!I1:I446,"Blocked") -> 0
B12: Not Executed | C12: =COUNTIF('Manual Test Cases'!I1:I446,"Not Executed") -> 0
B13: Pass Rate | C13: =IFERROR(COUNTIF('Manual Test Cases'!I1:I446,"Pass")/COUNTA('Manual Test Cases'!C1:C446),0) -> 0.99775785
B14: High Priority Cases | C14: =COUNTIF('Manual Test Cases'!J1:J446,"High") -> 59
B15: Medium Priority Cases | C15: =COUNTIF('Manual Test Cases'!J1:J446,"Medium") -> 252
B16: Low Priority Cases | C16: =COUNTIF('Manual Test Cases'!J1:J446,"Low") -> 134
B18: Test Cases by Scenario
B19: Test Scenario | C19: Count
B20: Homepage & Page Load | C20: =COUNTIF('Manual Test Cases'!B1:B446,"Homepage & Page Load") -> 14
B21: Ingredient Input - Functional | C21: =COUNTIF('Manual Test Cases'!B1:B446,"Ingredient Input - Functional") -> 25
B22: Input Validation & Edge Cases | C22: =COUNTIF('Manual Test Cases'!B1:B446,"Input Validation & Edge Cases") -> 42
B23: Recipe Generation Output | C23: =COUNTIF('Manual Test Cases'!B1:B446,"Recipe Generation Output") -> 30
B24: Recipe Detail Interactions | C24: =COUNTIF('Manual Test Cases'!B1:B446,"Recipe Detail Interactions") -> 20
B25: Responsive Design | C25: =COUNTIF('Manual Test Cases'!B1:B446,"Responsive Design") -> 28
B26: Cross-Browser Compatibility | C26: =COUNTIF('Manual Test Cases'!B1:B446,"Cross-Browser Compatibility") -> 24
B27: Accessibility | C27: =COUNTIF('Manual Test Cases'!B1:B446,"Accessibility") -> 25
B28: Security & Privacy | C28: =COUNTIF('Manual Test Cases'!B1:B446,"Security & Privacy") -> 20
B29: Performance & Load | C29: =COUNTIF('Manual Test Cases'!B1:B446,"Performance & Load") -> 15
B30: Error Handling & Network Conditions | C30: =COUNTIF('Manual Test Cases'!B1:B446,"Error Handling & Network Conditions") -> 20
B31: Navigation & Links | C31: =COUNTIF('Manual Test Cases'!B1:B446,"Navigation & Links") -> 15
B32: SEO & Metadata | C32: =COUNTIF('Manual Test Cases'!B1:B446,"SEO & Metadata") -> 10
B33: Session, State & Browser Storage | C33: =COUNTIF('Manual Test Cases'!B1:B446,"Session, State & Browser Storage") -> 10
B34: Notifications, Toasts & Alerts | C34: =COUNTIF('Manual Test Cases'!B1:B446,"Notifications, Toasts & Alerts") -> 10
B35: Content & Copy Quality | C35: =COUNTIF('Manual Test Cases'!B1:B446,"Content & Copy Quality") -> 10
B36: Device & OS Compatibility | C36: =COUNTIF('Manual Test Cases'!B1:B446,"Device & OS Compatibility") -> 10
B37: Localization & Internationalization | C37: =COUNTIF('Manual Test Cases'!B1:B446,"Localization & Internationalization") -> 10
B38: Usability | C38: =COUNTIF('Manual Test Cases'!B1:B446,"Usability") -> 15
B39: Print Functionality | C39: =COUNTIF('Manual Test Cases'!B1:B446,"Print Functionality") -> 8
B40: Ingredient-Category-Specific Generation | C40: =COUNTIF('Manual Test Cases'!B1:B446,"Ingredient-Category-Specific Generation") -> 30
B41: Dietary & Recipe Filters | C41: =COUNTIF('Manual Test Cases'!B1:B446,"Dietary & Recipe Filters") -> 20
B42: API & Backend Response Validation | C42: =COUNTIF('Manual Test Cases'!B1:B446,"API & Backend Response Validation") -> 15
B43: Load & Stress Testing | C43: =COUNTIF('Manual Test Cases'!B1:B446,"Load & Stress Testing") -> 10
...
